Workbook

Sheet 750 Pieces
A1: ID | B1: Timestamp | C1: Item Number | D1: Shape Code | E1: Shape Name | F1: Error (%) | G1: RPM | H1: Set Hz | I1: Synchronous Speed | J1: Slip % | K1: Speed (m/s) | L1: Cycle Speed | M1: Image File | N1: Accuracy
A2: 800 | B2: 2026-09-03 19:48:41 | C2: 750 | D2: 6 | E2: Blue Square | F2: 1.4 | G2: 1192 | H2: 40 | I2: 1200 | J2: 0.67 | K2: 0.162 | L2: 3.5 | M2: item_000750_20260903_194841.jpg | N2: 1
A3: 799 | B3: 2026-09-03 19:48:34 | C3: 749 | D3: 7 | E3: Yellow Circle | F3: 2.9 | G3: 1193 | H3: 40 | I3: 1200 | J3: 0.58 | K3: 0.162 | L3: 3.5 | M3: item_000749_20260903_194834.jpg | N3: 1
A4: 798 | B4: 2026-09-03 19:48:28 | C4: 748 | D4: 3 | E4: Red Square | F4: 1.2 | G4: 1192 | H4: 40 | I4: 1200 | J4: 0.67 | K4: 0.162 | L4: 3.5 | M4: item_000748_20260903_194827.jpg | N4: 1
A5: 797 | B5: 2026-09-03 19:48:19 | C5: 747 | D5: 11 | E5: Error Detected | F5: 21.9 | G5: 1190 | H5: 40 | I5: 1200 | J5: 0.83 | K5: 0.162 | L5: 3.5 | M5: item_000747_20260903_194819.jpg | N5: 1
A6: 796 | B6: 2026-09-03 19:48:12 | C6: 746 | D6: 11 | E6: Error Detected | F6: 19.4 | G6: 1192 | H6: 40 | I6: 1200 | J6: 0.67 | K6: 0.162 | L6: 3.5 | M6: item_000746_20260903_194812.jpg | N6: 1
A7: 795 | B7: 2026-09-03 19:48:07 | C7: 745 | D7: 4 | E7: Blue Circle | F7: 2.3 | G7: 1188 | H7: 40 | I7: 1200 | J7: 1 | K7: 0.162 | L7: 3.5 | M7: item_000745_20260903_194807.jpg | N7: 1
A8: 794 | B8: 2026-09-03 19:48:01 | C8: 744 | D8: 11 | E8: Error Detected | F8: 19.8 | G8: 1191 | H8: 40 | I8: 1200 | J8: 0.75 | K8: 0.162 | L8: 3.5 | M8: item_000744_20260903_194801.jpg | N8: 1
A9: 793 | B9: 2026-09-03 19:47:56 | C9: 743 | D9: 11 | E9: Error Detected | F9: 19.3 | G9: 1188 | H9: 40 | I9: 1200 | J9: 1 | K9: 0.162 | L9: 3.5 | M9: item_000743_20260903_194756.jpg | N9: 1
A10: 792 | B10: 2026-09-03 19:47:49 | C10: 742 | D10: 5 | E10: Blue Triangle | F10: 1.1 | G10: 1192 | H10: 40 | I10: 1200 | J10: 0.67 | K10: 0.162 | L10: 3.5 | M10: item_000742_20260903_194749.jpg | N10: 1
A11: 791 | B11: 2026-09-03 19:47:44 | C11: 741 | D11: 8 | E11: Yellow Triangle | F11: 2.1 | G11: 1187 | H11: 40 | I11: 1200 | J11: 1.08 | K11: 0.161 | L11: 3.5 | M11: item_000741_20260903_194744.jpg | N11: 1
A12: 790 | B12: 2026-09-03 19:47:37 | C12: 740 | D12: 1 | E12: Red Circle | F12: 2.9 | G12: 1192 | H12: 40 | I12: 1200 | J12: 0.67 | K12: 0.162 | L12: 3.5 | M12: item_000740_20260903_194737.jpg | N12: 1
A13: 789 | B13: 2026-09-03 19:47:31 | C13: 739 | D13: 9 | E13: Yellow Square | F13: 1.6 | G13: 1192 | H13: 40 | I13: 1200 | J13: 0.67 | K13: 0.162 | L13: 3.5 | M13: item_000739_20260903_194731.jpg | N13: 1
... A765: 1 | B765: 2026-09-02 22:06:15 | C765: 1 | D765: 9 | E765: Yellow Square | F765: 0.9 | G765: 585 | H765: 20 | I765: 600 | J765: 2.5 | K765: 0.079 | L765: 7.1 | M765: item_000001_20260902_220615.jpg | N765: 1
B767: 20 Hz | C767: 25 Hz | D767: 30 Hz | E767: 35 Hz | F767: 40 Hz | I767: Correct | J767: Incorrect | K767: m/s
A768: 1 | B768: {=INDEX($J$716:$J$765, 817 - ROW() + 1)} -> 2.5 | C768: {=INDEX($J$665:$J$714, 817 - ROW() + 1)} -> 1.87 | D768: {=INDEX($J$614:$J$663, 817 - ROW() + 1)} -> 1.11 | E768: {=INDEX($J$563:$J$612, 817 - ROW() + 1)} -> 1.33 | F768: {=INDEX($J$512:$J$561, 817 - ROW() + 1)} -> 1.42 | H768: 20 | I768: =AVERAGE(N716:N765,N461:N510,N206:N255) -> 0.96666667 | J768: =100%-I768 -> 0.033333333 | K768: =AVERAGE(K206:K255,K461:K510,K716:K765) -> 0.079453333
A769: 2 | B769: {=INDEX($J$716:$J$765, 817 - ROW() + 1)} -> 2.17 | C769: {=INDEX($J$665:$J$714, 817 - ROW() + 1)} -> 1.73 | D769: {=INDEX($J$614:$J$663, 817 - ROW() + 1)} -> 1 | E769: {=INDEX($J$563:$J$612, 817 - ROW() + 1)} -> 1.33 | F769: {=INDEX($J$512:$J$561, 817 - ROW() + 1)} -> 1.17 | H769: 25 | I769: =AVERAGE(N155:N204,N410:N459,N665:N714) -> 0.97333333 | J769: =100%-I769 -> 0.026666667 | K769: =AVERAGE(K155:K204,K410:K459,K665:K714) -> 0.099586667
A770: 3 | B770: {=INDEX($J$716:$J$765, 817 - ROW() + 1)} -> 2.5 | C770: {=INDEX($J$665:$J$714, 817 - ROW() + 1)} -> 1.73 | D770: {=INDEX($J$614:$J$663, 817 - ROW() + 1)} -> 1.22 | E770: {=INDEX($J$563:$J$612, 817 - ROW() + 1)} -> 1.05 | F770: {=INDEX($J$512:$J$561, 817 - ROW() + 1)} -> 1.25 | H770: 30 | I770: =AVERAGE(N104:N153,N359:N408,N614:N663) -> 0.99333333 | J770: =100%-I770 -> 0.0066666667 | K770: =AVERAGE(K104:K153,K359:K408,K614:K663) -> 0.12008667
A771: 4 | B771: {=INDEX($J$716:$J$765, 817 - ROW() + 1)} -> 2.33 | C771: {=INDEX($J$665:$J$714, 817 - ROW() + 1)} -> 1.6 | D771: {=INDEX($J$614:$J$663, 817 - ROW() + 1)} -> 1.33 | E771: {=INDEX($J$563:$J$612, 817 - ROW() + 1)} -> 0.95 | F771: {=INDEX($J$512:$J$561, 817 - ROW() + 1)} -> 1.17 | H771: 35 | I771: =AVERAGE(N563:N612,N308:N357,N53:N102) -> 0.98 | J771: =100%-I771 -> 0.02 | K771: =AVERAGE(K53:K102,K308:K357,K563:K612) -> 0.14049333
A772: 5 | B772: {=INDEX($J$716:$J$765, 817 - ROW() + 1)} -> 2.17 | C772: {=INDEX($J$665:$J$714, 817 - ROW() + 1)} -> 2 | D772: {=INDEX($J$614:$J$663, 817 - ROW() + 1)} -> 1.22 | E772: {=INDEX($J$563:$J$612, 817 - ROW() + 1)} -> 1.14 | F772: {=INDEX($J$512:$J$561, 817 - ROW() + 1)} -> 1.25 | H772: 40 | I772: =AVERAGE(N2:N51,N257:N306,N512:N561) -> 0.93333333 | J772: =100%-I772 -> 0.066666667 | K772: =AVERAGE(K2:K51,K257:K306,K512:K561) -> 0.1619
A773: 6 | B773: {=INDEX($J$716:$J$765, 817 - ROW() + 1)} -> 2.17 | C773: {=INDEX($J$665:$J$714, 817 - ROW() + 1)} -> 1.87 | D773: {=INDEX($J$614:$J$663, 817 - ROW() + 1)} -> 1.22 | E773: {=INDEX($J$563:$J$612, 817 - ROW() + 1)} -> 1.05 | F773: {=INDEX($J$512:$J$561, 817 - ROW() + 1)} -> 0.92 | H773: Overall | I773: =AVERAGE(N2:N765) -> 0.96933333 | J773: =100%-I773 -> 0.030666667
A774: 7 | B774: {=INDEX($J$716:$J$765, 817 - ROW() + 1)} -> 2.17 | C774: {=INDEX($J$665:$J$714, 817 - ROW() + 1)} -> 2 | D774: {=INDEX($J$614:$J$663, 817 - ROW() + 1)} -> 1.22 | E774: {=INDEX($J$563:$J$612, 817 - ROW() + 1)} -> 0.86 | F774: {=INDEX($J$512:$J$561, 817 - ROW() + 1)} -> 1 | I774: Correct | J774: Incorrect
A775: 8 | B775: {=INDEX($J$716:$J$765, 817 - ROW() + 1)} -> 2.33 | C775: {=INDEX($J$665:$J$714, 817 - ROW() + 1)} -> 1.73 | D775: {=INDEX($J$614:$J$663, 817 - ROW() + 1)} -> 1 | E775: {=INDEX($J$563:$J$612, 817 - ROW() + 1)} -> 0.76 | F775: {=INDEX($J$512:$J$561, 817 - ROW() + 1)} -> 0.83 | I775: =AVERAGE(N4:N767) -> 0.96925134 | J775: =100%-I775 -> 0.030748663
A776: 9 | B776: {=INDEX($J$716:$J$765, 817 - ROW() + 1)} -> 2.33 | C776: {=INDEX($J$665:$J$714, 817 - ROW() + 1)} -> 1.87 | D776: {=INDEX($J$614:$J$663, 817 - ROW() + 1)} -> 1.22 | E776: {=INDEX($J$563:$J$612, 817 - ROW() + 1)} -> 1.05 | F776: {=INDEX($J$512:$J$561, 817 - ROW() + 1)} -> 1 | I776: =COUNTIF(N2:N765, 1) -> 727 | J776: =COUNTIF(N2:N765, 0) -> 23
A777: 10 | B777: {=INDEX($J$716:$J$765, 817 - ROW() + 1)} -> 2.17 | C777: {=INDEX($J$665:$J$714, 817 - ROW() + 1)} -> 2 | D777: {=INDEX($J$614:$J$663, 817 - ROW() + 1)} -> 1.11 | E777: {=INDEX($J$563:$J$612, 817 - ROW() + 1)} -> 0.95 | F777: {=INDEX($J$512:$J$561, 817 - ROW() + 1)} -> 1.17
A778: 11 | B778: {=INDEX($J$716:$J$765, 817 - ROW() + 1)} -> 1.83 | C778: {=INDEX($J$665:$J$714, 817 - ROW() + 1)} -> 1.73 | D778: {=INDEX($J$614:$J$663, 817 - ROW() + 1)} -> 1.22 | E778: {=INDEX($J$563:$J$612, 817 - ROW() + 1)} -> 1.05 | F778: {=INDEX($J$512:$J$561, 817 - ROW() + 1)} -> 1 | H778: 1
A779: 12 | B779: {=INDEX($J$716:$J$765, 817 - ROW() + 1)} -> 2.33 | C779: {=INDEX($J$665:$J$714, 817 - ROW() + 1)} -> 2 | D779: {=INDEX($J$614:$J$663, 817 - ROW() + 1)} -> 1.22 | E779: {=INDEX($J$563:$J$612, 817 - ROW() + 1)} -> 0.86 | F779: {=INDEX($J$512:$J$561, 817 - ROW() + 1)} -> 1 | H779: 2
A780: 13 | B780: {=INDEX($J$716:$J$765, 817 - ROW() + 1)} -> 2.33 | C780: {=INDEX($J$665:$J$714, 817 - ROW() + 1)} -> 1.6 | D780: {=INDEX($J$614:$J$663, 817 - ROW() + 1)} -> 0.89 | E780: {=INDEX($J$563:$J$612, 817 - ROW() + 1)} -> 1.05 | F780: {=INDEX($J$512:$J$561, 817 - ROW() + 1)} -> 1.08 | H780: 3
A781: 14 | B781: {=INDEX($J$716:$J$765, 817 - ROW() + 1)} -> 2.17 | C781: {=INDEX($J$665:$J$714, 817 - ROW() + 1)} -> 1.73 | D781: {=INDEX($J$614:$J$663, 817 - ROW() + 1)} -> 1 | E781: {=INDEX($J$563:$J$612, 817 - ROW() + 1)} -> 0.86 | F781: {=INDEX($J$512:$J$561, 817 - ROW() + 1)} -> 1 | H781: 4
A782: 15 | B782: {=INDEX($J$716:$J$765, 817 - ROW() + 1)} -> 2.17 | C782: {=INDEX($J$665:$J$714, 817 - ROW() + 1)} -> 1.6 | D782: {=INDEX($J$614:$J$663, 817 - ROW() + 1)} -> 1.11 | E782: {=INDEX($J$563:$J$612, 817 - ROW() + 1)} -> 0.86 | F782: {=INDEX($J$512:$J$561, 817 - ROW() + 1)} -> 1.08 | H782: 5
A783: 16 | B783: {=INDEX($J$716:$J$765, 817 - ROW() + 1)} -> 2.17 | C783: {=INDEX($J$665:$J$714, 817 - ROW() + 1)} -> 1.6 | D783: {=INDEX($J$614:$J$663, 817 - ROW() + 1)} -> 1.11 | E783: {=INDEX($J$563:$J$612, 817 - ROW() + 1)} -> 1.24 | F783: {=INDEX($J$512:$J$561, 817 - ROW() + 1)} -> 0.92 | H783: 6
A784: 17 | B784: {=INDEX($J$716:$J$765, 817 - ROW() + 1)} -> 2.33 | C784: {=INDEX($J$665:$J$714, 817 - ROW() + 1)} -> 1.73 | D784: {=INDEX($J$614:$J$663, 817 - ROW() + 1)} -> 1 | E784: {=INDEX($J$563:$J$612, 817 - ROW() + 1)} -> 0.95 | F784: {=INDEX($J$512:$J$561, 817 - ROW() + 1)} -> 1 | H784: 7
A785: 18 | B785: {=INDEX($J$716:$J$765, 817 - ROW() + 1)} -> 1.83 | C785: {=INDEX($J$665:$J$714, 817 - ROW() + 1)} -> 1.6 | D785: {=INDEX($J$614:$J$663, 817 - ROW() + 1)} -> 1 | E785: {=INDEX($J$563:$J$612, 817 - ROW() + 1)} -> 0.86 | F785: {=INDEX($J$512:$J$561, 817 - ROW() + 1)} -> 0.92 | H785: 8
A786: 19 | B786: {=INDEX($J$716:$J$765, 817 - ROW() + 1)} -> 2.33 | C786: {=INDEX($J$665:$J$714, 817 - ROW() + 1)} -> 1.87 | D786: {=INDEX($J$614:$J$663, 817 - ROW() + 1)} -> 1.22 | E786: {=INDEX($J$563:$J$612, 817 - ROW() + 1)} -> 0.86 | F786: {=INDEX($J$512:$J$561, 817 - ROW() + 1)} -> 1 | H786: 9
A787: 20 | B787: {=INDEX($J$716:$J$765, 817 - ROW() + 1)} -> 2.33 | C787: {=INDEX($J$665:$J$714, 817 - ROW() + 1)} -> 1.6 | D787: {=INDEX($J$614:$J$663, 817 - ROW() + 1)} -> 1 | E787: {=INDEX($J$563:$J$612, 817 - ROW() + 1)} -> 1.14 | F787: {=INDEX($J$512:$J$561, 817 - ROW() + 1)} -> 0.75 | H787: 10
A788: 21 | B788: {=INDEX($J$716:$J$765, 817 - ROW() + 1)} -> 2.33 | C788: {=INDEX($J$665:$J$714, 817 - ROW() + 1)} -> 1.73 | D788: {=INDEX($J$614:$J$663, 817 - ROW() + 1)} -> 1.22 | E788: {=INDEX($J$563:$J$612, 817 - ROW() + 1)} -> 0.86 | F788: {=INDEX($J$512:$J$561, 817 - ROW() + 1)} -> 0.83 | H788: 11
A789: 22 | B789: {=INDEX($J$716:$J$765, 817 - ROW() + 1)} -> 2.33 | C789: {=INDEX($J$665:$J$714, 817 - ROW() + 1)} -> 1.6 | D789: {=INDEX($J$614:$J$663, 817 - ROW() + 1)} -> 1 | E789: {=INDEX($J$563:$J$612, 817 - ROW() + 1)} -> 1.05 | F789: {=INDEX($J$512:$J$561, 817 - ROW() + 1)} -> 1 | H789: 12
... A817: 50 | B817: {=INDEX($J$716:$J$765, 817 - ROW() + 1)} -> 1.83 | C817: {=INDEX($J$665:$J$714, 817 - ROW() + 1)} -> 1.47 | D817: {=INDEX($J$614:$J$663, 817 - ROW() + 1)} -> 1.33 | E817: {=INDEX($J$563:$J$612, 817 - ROW() + 1)} -> 1.14 | F817: {=INDEX($J$512:$J$561, 817 - ROW() + 1)} -> 1.08 | H817: 40
A818: 51 | B818: {=INDEX($J$461:$J$510, 867 - ROW() + 1)} -> 2.67 | C818: {=INDEX($J$410:$J$459, 867 - ROW() + 1)} -> 1.6 | D818: {=INDEX($J$359:$J$408, 867 - ROW() + 1)} -> 1.11 | E818: {=INDEX($J$308:$J$357, 867 - ROW() + 1)} -> 1.33 | F818: {=INDEX($J$257:$J$306, 867 - ROW() + 1)} -> 1.08 | H818: 41
A819: 52 | B819: {=INDEX($J$461:$J$510, 867 - ROW() + 1)} -> 2.17 | C819: {=INDEX($J$410:$J$459, 867 - ROW() + 1)} -> 1.47 | D819: {=INDEX($J$359:$J$408, 867 - ROW() + 1)} -> 1 | E819: {=INDEX($J$308:$J$357, 867 - ROW() + 1)} -> 1.33 | F819: {=INDEX($J$257:$J$306, 867 - ROW() + 1)} -> 0.75 | H819: 42
...

Sheet 750 Pieces (2)
A1: No | B1: Code | C1: Shape Name | D1: Error (%) | E1: RPM | F1: Hz | G1: %Slip | H1: Speed (m/s)
A2: 750 | B2: 6 | C2: Blue Square | D2: 1.4 | E2: 1192 | F2: 40 | G2: 0.67 | H2: 0.162
A3: 749 | B3: 7 | C3: Yellow Circle | D3: 2.9 | E3: 1193 | F3: 40 | G3: 0.58 | H3: 0.162
A4: 748 | B4: 3 | C4: Red Square | D4: 1.2 | E4: 1192 | F4: 40 | G4: 0.67 | H4: 0.162
A5: 747 | B5: 11 | C5: Error Detected | D5: 21.9 | E5: 1190 | F5: 40 | G5: 0.83 | H5: 0.162
A6: 746 | B6: 11 | C6: Error Detected | D6: 19.4 | E6: 1192 | F6: 40 | G6: 0.67 | H6: 0.162
A7: 745 | B7: 4 | C7: Blue Circle | D7: 2.3 | E7: 1188 | F7: 40 | G7: 1 | H7: 0.162
A8: 744 | B8: 11 | C8: Error Detected | D8: 19.8 | E8: 1191 | F8: 40 | G8: 0.75 | H8: 0.162
A9: 743 | B9: 11 | C9: Error Detected | D9: 19.3 | E9: 1188 | F9: 40 | G9: 1 | H9: 0.162
A10: 742 | B10: 5 | C10: Blue Triangle | D10: 1.1 | E10: 1192 | F10: 40 | G10: 0.67 | H10: 0.162
A11: 741 | B11: 8 | C11: Yellow Triangle | D11: 2.1 | E11: 1187 | F11: 40 | G11: 1.08 | H11: 0.161
A12: 740 | B12: 1 | C12: Red Circle | D12: 2.9 | E12: 1192 | F12: 40 | G12: 0.67 | H12: 0.162
A13: 739 | B13: 9 | C13: Yellow Square | D13: 1.6 | E13: 1192 | F13: 40 | G13: 0.67 | H13: 0.162
... A51: 701 | B51: 6 | C51: Blue Square | D51: 1.2 | E51: 1188 | F51: 40 | G51: 1 | H51: 0.162
A52: No | B52: Code | C52: Shape Name | D52: Error (%) | E52: RPM | F52: Hz | G52: %Slip | H52: Speed (m/s)
A53: 700 | B53: 7 | C53: Yellow Circle | D53: 2.9 | E53: 1038 | F53: 35 | G53: 1.14 | H53: 0.141
A54: 699 | B54: 6 | C54: Blue Square | D54: 1.1 | E54: 1040 | F54: 35 | G54: 0.95 | H54: 0.141
A55: 698 | B55: 1 | C55: Red Circle | D55: 2.8 | E55: 1039 | F55: 35 | G55: 1.05 | H55: 0.141
A56: 697 | B56: 11 | C56: Error Detected | D56: 19.5 | E56: 1038 | F56: 35 | G56: 1.14 | H56: 0.141
A57: 696 | B57: 11 | C57: Error Detected | D57: 13.9 | E57: 1040 | F57: 35 | G57: 0.95 | H57: 0.141
A58: 695 | B58: 1 | C58: Red Circle | D58: 2.8 | E58: 1039 | F58: 35 | G58: 1.05 | H58: 0.141
A59: 694 | B59: 5 | C59: Blue Triangle | D59: 1.1 | E59: 1039 | F59: 35 | G59: 1.05 | H59: 0.141
A60: 693 | B60: 11 | C60: Error Detected | D60: 35.4 | E60: 1038 | F60: 35 | G60: 1.14 | H60: 0.141
A61: 692 | B61: 9 | C61: Yellow Square | D61: 1.5 | E61: 1040 | F61: 35 | G61: 0.95 | H61: 0.141
A62: 691 | B62: 4 | C62: Blue Circle | D62: 2.3 | E62: 1041 | F62: 35 | G62: 0.86 | H62: 0.142
A63: 690 | B63: 11 | C63: Error Detected | D63: 18.9 | E63: 1040 | F63: 35 | G63: 0.95 | H63: 0.141
A64: 689 | B64: 1 | C64: Red Circle | D64: 2.8 | E64: 1041 | F64: 35 | G64: 0.86 | H64: 0.142
... A102: 651 | B102: 1 | C102: Red Circle | D102: 2.9 | E102: 1041 | F102: 35 | G102: 0.86 | H102: 0.142
A103: No | B103: Code | C103: Shape Name | D103: Error (%) | E103: RPM | F103: Hz | G103: %Slip | H103: Speed (m/s)
A104: 650 | B104: 8 | C104: Yellow Triangle | D104: 2.3 | E104: 888 | F104: 30 | G104: 1.33 | H104: 0.121
A105: 649 | B105: 2 | C105: Red Triangle | D105: 1.2 | E105: 886 | F105: 30 | G105: 1.56 | H105: 0.12
A106: 648 | B106: 6 | C106: Blue Square | D106: 1.2 | E106: 889 | F106: 30 | G106: 1.22 | H106: 0.121
A107: 647 | B107: 8 | C107: Yellow Triangle | D107: 2.4 | E107: 889 | F107: 30 | G107: 1.22 | H107: 0.121
A108: 646 | B108: 11 | C108: Error Detected | D108: 17 | E108: 887 | F108: 30 | G108: 1.44 | H108: 0.121
A109: 645 | B109: 3 | C109: Red Square | D109: 3.3 | E109: 889 | F109: 30 | G109: 1.22 | H109: 0.121
A110: 644 | B110: 3 | C110: Red Square | D110: 1.2 | E110: 886 | F110: 30 | G110: 1.56 | H110: 0.12
A111: 643 | B111: 9 | C111: Yellow Square | D111: 1.4 | E111: 886 | F111: 30 | G111: 1.56 | H111: 0.12
A112: 642 | B112: 7 | C112: Yellow Circle | D112: 2.8 | E112: 890 | F112: 30 | G112: 1.11 | H112: 0.121
A113: 641 | B113: 3 | C113: Red Square | D113: 1.2 | E113: 886 | F113: 30 | G113: 1.56 | H113: 0.121
A114: 640 | B114: 9 | C114: Yellow Square | D114: 1.2 | E114: 888 | F114: 30 | G114: 1.33 | H114: 0.121
...

Sheet Results1
A1: Set Hz | B1: Slip(%)
A2: 20 | B2: =AVERAGE('750 Pieces'!J716:J765,'750 Pieces'!J461:J510,'750 Pieces'!J206:J255) -> 2.1437333
A3: 25 | B3: =AVERAGE('750 Pieces'!J665:J714,'750 Pieces'!J410:J459,'750 Pieces'!J155:J204) -> 1.6246
A4: 30 | B4: =AVERAGE('750 Pieces'!J614:J663,'750 Pieces'!J359:J408,'750 Pieces'!J104:J153) -> 1.2290667
A5: 35 | B5: =AVERAGE('750 Pieces'!J563:J612,'750 Pieces'!J308:J357,'750 Pieces'!J53:J102) -> 0.98646667
A6: 40 | B6: =AVERAGE('750 Pieces'!J2:J51,'750 Pieces'!J257:J306,'750 Pieces'!J512:J561) -> 0.85386667
A21: %Slip at 20 Hz
A40: %Slip at 25 Hz
A59: %Slip at 30 Hz
A78: %Slip at 35 Hz
A97: %Slip at 35 Hz
A116: %Slip All

Sheet Results2
A1: ความถูกต้องในการตรวจจับ (750 ครั้ง)
A17: ความถูกต้องในแต่ละระดับความถี่

Sheet AI vs Human
A1: ID | B1: Timestamp | C1: Item Number | D1: Shape Code | E1: Shape Name | F1: Error (%) | G1: RPM | H1: Set Hz | I1: Synchronous Speed | J1: Slip % | K1: Speed (m/s) | L1: Cycle Speed | M1: Image File
A2: 820 | B2: 2026-09-06 15:47:20 | C2: 770 | D2: 5 | E2: Blue Triangle | F2: 1 | G2: 1186 | H2: 40 | I2: 1200 | J2: 1.17 | K2: 0.161 | L2: 3.5 | M2: item_000770_20260906_154720.jpg
A3: 819 | B3: 2026-09-06 15:47:10 | C3: 769 | D3: 8 | E3: Yellow Triangle | F3: 2.1 | G3: 1188 | H3: 40 | I3: 1200 | J3: 1 | K3: 0.162 | L3: 3.5 | M3: item_000769_20260906_154710.jpg
A4: 818 | B4: 2026-09-06 15:47:00 | C4: 768 | D4: 2 | E4: Red Triangle | F4: 1.3 | G4: 1189 | H4: 40 | I4: 1200 | J4: 0.92 | K4: 0.162 | L4: 3.5 | M4: item_000768_20260906_154700.jpg
A5: 817 | B5: 2026-09-06 15:46:51 | C5: 767 | D5: 9 | E5: Yellow Square | F5: 1.1 | G5: 1191 | H5: 40 | I5: 1200 | J5: 0.75 | K5: 0.162 | L5: 3.5 | M5: item_000767_20260906_154651.jpg
A6: 816 | B6: 2026-09-06 15:46:40 | C6: 766 | D6: 6 | E6: Blue Square | F6: 1.4 | G6: 1188 | H6: 40 | I6: 1200 | J6: 1 | K6: 0.162 | L6: 3.5 | M6: item_000766_20260906_154640.jpg
A7: 815 | B7: 2026-09-06 15:46:30 | C7: 765 | D7: 7 | E7: Yellow Circle | F7: 2.9 | G7: 1188 | H7: 40 | I7: 1200 | J7: 1 | K7: 0.162 | L7: 3.5 | M7: item_000765_20260906_154630.jpg
A8: 814 | B8: 2026-09-06 15:46:23 | C8: 764 | D8: 4 | E8: Blue Circle | F8: 2.5 | G8: 1186 | H8: 40 | I8: 1200 | J8: 1.17 | K8: 0.161 | L8: 3.5 | M8: item_000764_20260906_154623.jpg
A9: 813 | B9: 2026-09-06 15:46:12 | C9: 763 | D9: 12 | E9: Object Not Found | F9: 0 | G9: 1190 | H9: 40 | I9: 1200 | J9: 0.83 | K9: 0.162 | L9: 3.5 | M9: item_000763_20260906_154612.jpg
A10: 812 | B10: 2026-09-06 15:46:04 | C10: 762 | D10: 3 | E10: Red Square | F10: 1 | G10: 1188 | H10: 40 | I10: 1200 | J10: 1 | K10: 0.162 | L10: 3.5 | M10: item_000762_20260906_154604.jpg
A11: 811 | B11: 2026-09-06 15:45:53 | C11: 761 | D11: 5 | E11: Blue Triangle | F11: 1.2 | G11: 1189 | H11: 40 | I11: 1200 | J11: 0.92 | K11: 0.162 | L11: 3.5 | M11: item_000761_20260906_154553.jpg
A12: 810 | B12: 2026-09-06 15:45:43 | C12: 760 | D12: 8 | E12: Yellow Triangle | F12: 2.1 | G12: 1190 | H12: 40 | I12: 1200 | J12: 0.83 | K12: 0.162 | L12: 3.5 | M12: item_000760_20260906_154543.jpg
A13: 809 | B13: 2026-09-06 15:45:34 | C13: 759 | D13: 2 | E13: Red Triangle | F13: 1.3 | G13: 1185 | H13: 40 | I13: 1200 | J13: 1.25 | K13: 0.161 | L13: 3.5 | M13: item_000759_20260906_154534.jpg
... A21: 801 | B21: 2026-09-06 15:44:05 | C21: 751 | D21: 8 | E21: Yellow Triangle | F21: 2.3 | G21: 1183 | H21: 40 | I21: 1200 | J21: 1.42 | K21: 0.161 | L21: 3.5 | M21: item_000751_20260906_154405.jpg
A23: เริ่ม | B23: 0.65561343
A24: เสร็จสิ้น | B24: 0.65787037
A25: เวลาที่ใข้ | B25: 3 นาที 15 วินาที | C25: 195 วินาที
A28: No. | B28: Name | C28: Error% | D28: RPM | E28: Conveyor Speed
A29: 1 | B29: Yellow Triangle | C29: 2.3 | D29: 1185 | E29: 0.16
A30: 2 | B30: Blue Triangle | C30: 1.1 | D30: 1185 | E30: 0.16
A31: 3 | B31: Red Square | C31: 1 | D31: 1188 | E31: 0.16
A32: 4 | B32: Red Circle | C32: 2.7 | D32: 1188 | E32: 0.16
A33: 5 | B33: Blue Circle | C33: 2.4 | D33: 1189 | E33: 0.16
A34: 6 | B34: Yellow Circle | C34: 2.9 | D34: 1186 | E34: 0.16
A35: 7 | B35: Blue Square | C35: 1.2 | D35: 1188 | E35: 0.16
A36: 8 | B36: Yellow Square | C36: 1.2 | D36: 1188 | E36: 0.16
A37: 9 | B37: Red Triangle | C37: 1.3 | D37: 1190 | E37: 0.16
A38: 10 | B38: Yellow Triangle | C38: 2.1 | D38: 1188 | E38: 0.16
A39: 11 | B39: Blue Triangle | C39: 1.2 | D39: 1188 | E39: 0.16
A40: 12 | B40: Red Square | C40: 1 | D40: 1189 | E40: 0.16
... A48: 20 | B48: Blue Triangle | C48: 1 | D48: 1189 | E48: 0.16
A49: ใช้เวลาทั้งหมด | B49: 6 นาที 40 วินาที | C49: 400 วินาที

Sheet Worthiness Results
A1: ประเภทระบบ | B1: ค่าความถี่ที่ใช้ทดลอง (Hz) | C1: จำนวนครั้งการทดสอบ (ครั้ง) | D1: เวลาที่ใช้ทั้งหมด (วินาที) | E1: เวลาเฉลี่ยต่อชิ้น (วินาที) | F1: กำลังการผลิตต่อวัน (ชิ้น/วัน) | G1: ประสิทธิภาพที่เพิ่มขึ้น (%) | H1: ต้นทุนระบบอัตโนมัติ (บาท)
A2: แรงงานคน | B2: 40 | C2: 20 | D2: 400 | E2: 20 | F2: =28800/E2 -> 1440 | G2: =(E2-E3)/E2 -> 0.5125 | H2: ="-" -> -
A3: ระบบอัตโนมัติ | D3: 195 | E3: 9.75 | F3: =28800/E3 -> 2953.8462 | H3: 80670
A5: ประเภทระบบ | B5: ระยะเวลาทำงานต่อวัน (ชั่วโมง) | C5: วันทำงานต่อปี (วัน) | D5: อายุการใช้งานระบบ (ปี) | E5: ต้นทุนค่าเสื่อมสภาพ (บาท/ปี) | F5: ต้นทุนค่าเสื่อมสภาพ (บาท/วัน) | G5: ต้นทุนค่าเสื่อมสภาพต่อชิ้น (บาท/ชิ้น)
A6: แรงงานคน | B6: 8 | C6: 250 | D6: ="-" -> - | E6: ="-" -> - | F6: ="-" -> - | G6: ="-" -> -
A7: ระบบอัตโนมัติ | D7: 5 | E7: =H3/5 -> 16134 | F7: =E7/C6 -> 64.536 | G7: =F7/F3 -> 0.021848125
A9: ประเภทระบบ | B9: อัตราค่าไฟฟ้า (บาท/หน่วย) | C9: อัตราการใช้พลังงานไฟฟ้า (kwh) | D9: ค่าจ้างแรงงาน (บาท/วัน) | E9: ต้นทุนค่าแรงต่อชิ้น (บาท) | F9: ต้นทุนค่าพลังงานไฟฟ้าต่อชิ้น | G9: ต้นทุนสุทธิต่อชิ้น (บาท/ชิ้น) | H9: ต้นทุนที่ประหยัดได้ (บาท/ชิ้น)
A10: แรงงานคน | B10: 4 | C10: 0.28 | D10: 350 | E10: =D10/F2 -> 0.24305556 | F10: ="-" -> - | G10: =E10 -> 0.24305556 | H10: =G10-G11 -> 0.099684514
A11: ระบบอัตโนมัติ | D11: ="-" -> - | E11: =D10/F3 -> 0.11848958 | F11: =(B10*C10*B6)/F3 -> 0.0030333333 | G11: =E11+F11+G7 -> 0.14337104
E12: *ระบบอัตโนมัติคนคุม 1 คน | F12: *เฉพาะระบบอัตโนมัติ
A13: ประเภทระบบ | B13: ประหยัดต่อปี (บาท/ปี) | C13: ระยะเวลาคืนทุน (ปี)
A14: แรงงานคน | B14: =H10*F3*C6 -> 73613.179 | C14: =H3/B14 -> 1.0958635
A15: ระบบอัตโนมัติ
C16: *หรือประมาณ 1 ปี 1 เดือน
A54: ปีที่ | B54: กระแสเงินสดสุทธิประจำปี | C54: กระแสเงินสะสม
A55: 0 | B55: =-1*(H3) -> -80670 | C55: =B55 -> -80670
A56: 1 | B56: ="+73,613" -> +73,613 | C56: =C55+B56 -> -7057
A57: 2 | B57: ="+73,613" -> +73,613 | C57: =C56+B57 -> 66556
A58: 3 | B58: ="+73,613" -> +73,613 | C58: =C57+B58 -> 140169
A59: 4 | B59: ="+73,613" -> +73,613 | C59: =C58+B59 -> 213782
A60: 5 | B60: ="+73,613" -> +73,613 | C60: =C59+B60 -> 287395
